Workbook

Sheet Sales by Category
A3: Row Labels | B3: Sales by Category
A4: Furniture | B4: 741999.8
A5: Office Supplies | B5: 719047.03
A6: Technology | B6: 836154.03
A7: Grand Total | B7: 2297200.9

Sheet Sales by Region
A3: Row Labels | B3: Sales by Region
A4: Central | B4: 501239.89
A5: East | B5: 678781.24
A6: South | B6: 391721.91
A7: West | B7: 725457.82
A8: Grand Total | B8: 2297200.9

Sheet Monthly Sales Trend
A3: Row Labels | B3: Monthly Sales Trend
A4: 2014
A5: Jan | B5: 14236.895
A6: Feb | B6: 4519.892
A7: Mar | B7: 55691.009
A8: Apr | B8: 28295.345
A9: May | B9: 23648.287
A10: Jun | B10: 34595.128
A11: Jul | B11: 33946.393
A12: Aug | B12: 27909.468
A13: Sep | B13: 81777.351
A14: Oct | B14: 31453.393
A15: Nov | B15: 78628.717
A16: Dec | B16: 69545.62
A17: 2015
A18: Jan | B18: 18174.076
A19: Feb | B19: 11951.411
A20: Mar | B20: 38726.252
A21: Apr | B21: 34195.208
A22: May | B22: 30131.686
A23: Jun | B23: 24797.292
A24: Jul | B24: 28765.325
A25: Aug | B25: 36898.332
A26: Sep | B26: 64595.918
A27: Oct | B27: 31404.924
A28: Nov | B28: 75972.564
A29: Dec | B29: 74919.521
A30: 2016
A31: Jan | B31: 18542.491
A32: Feb | B32: 22978.815
A33: Mar | B33: 51715.875
A34: Apr | B34: 38750.039
A35: May | B35: 56987.728
A36: Jun | B36: 40344.534
A37: Jul | B37: 39261.963
A38: Aug | B38: 31115.374
A39: Sep | B39: 73410.025
A40: Oct | B40: 59687.745
A41: Nov | B41: 79411.966
A42: Dec | B42: 96999.043
...

Sheet Profit by Category
A3: Row Labels | B3: Sum of Profit
A4: Furniture | B4: 18451.273
A5: Office Supplies | B5: 122490.8
A6: Technology | B6: 145454.95
A7: Grand Total | B7: 286397.02

Sheet Sales by Segment
A3: Row Labels | B3: Sum of Sales
A4: Consumer | B4: 1161401.3
A5: Corporate | B5: 706146.37
A6: Home Office | B6: 429653.15
A7: Grand Total | B7: 2297200.9

Sheet Summary
A1: SUPERSTORE DATA ANALYSIS
A2: Total Sales | B2: Total Profit | C2: Total Quantity | D2: Number of Orders
A3: =Working!B2 -> 2297200.9 | B3: =Working!B3 -> 286397.02 | C3: =Working!B4 -> 37873 | D3: =Working!B7 -> 9994
A6: Average Sales | B6: Average Profit
A7: =Working!B5 -> 229.858 | B7: =Working!B6 -> 28.656896

Sheet Raw Data
A1: Row ID | B1: Order ID | C1: Order Date | D1: Ship Date | E1: Ship Mode | F1: Customer ID | G1: Customer Name | H1: Segment | I1: Country | J1: City | K1: State | L1: Postal Code | M1: Region | N1: Product ID | O1: Category | P1: Sub-Category | Q1: Product Name | R1: Sales | S1: Quantity | T1: Discount | U1: Profit
A2: 1 | B2: CA-2016-152156 | C2: 42682 | D2: 42685 | E2: Second Class | F2: CG-12520 | G2: Claire Gute | H2: Consumer | I2: United States | J2: Henderson | K2: Kentucky | L2: 42420 | M2: South | N2: FUR-BO-10001798 | O2: Furniture | P2: Bookcases | Q2: Bush Somerset Collection Bookcase | R2: 261.96 | S2: 2 | T2: 0 | U2: 41.9136
A3: 2 | B3: CA-2016-152156 | C3: 42682 | D3: 42685 | E3: Second Class | F3: CG-12520 | G3: Claire Gute | H3: Consumer | I3: United States | J3: Henderson | K3: Kentucky | L3: 42420 | M3: South | N3: FUR-CH-10000454 | O3: Furniture | P3: Chairs | Q3: Hon Deluxe Fabric Upholstered Stacking Chairs, Rounded Back | R3: 731.94 | S3: 3 | T3: 0 | U3: 219.582
A4: 3 | B4: CA-2016-138688 | C4: 42533 | D4: 42537 | E4: Second Class | F4: DV-13045 | G4: Darrin Van Huff | H4: Corporate | I4: United States | J4: Los Angeles | K4: California | L4: 90036 | M4: West | N4: OFF-LA-10000240 | O4: Office Supplies | P4: Labels | Q4: Self-Adhesive Address Labels for Typewriters by Universal | R4: 14.62 | S4: 2 | T4: 0 | U4: 6.8714
A5: 4 | B5: US-2015-108966 | C5: 42288 | D5: 42295 | E5: Standard Class | F5: SO-20335 | G5: Sean O'Donnell | H5: Consumer | I5: United States | J5: Fort Lauderdale | K5: Florida | L5: 33311 | M5: South | N5: FUR-TA-10000577 | O5: Furniture | P5: Tables | Q5: Bretford CR4500 Series Slim Rectangular Table | R5: 957.5775 | S5: 5 | T5: 0.45 | U5: -383.031
A6: 5 | B6: US-2015-108966 | C6: 42288 | D6: 42295 | E6: Standard Class | F6: SO-20335 | G6: Sean O'Donnell | H6: Consumer | I6: United States | J6: Fort Lauderdale | K6: Florida | L6: 33311 | M6: South | N6: OFF-ST-10000760 | O6: Office Supplies | P6: Storage | Q6: Eldon Fold 'N Roll Cart System | R6: 22.368 | S6: 2 | T6: 0.2 | U6: 2.5164
A7: 6 | B7: CA-2014-115812 | C7: 41799 | D7: 41804 | E7: Standard Class | F7: BH-11710 | G7: Brosina Hoffman | H7: Consumer | I7: United States | J7: Los Angeles | K7: California | L7: 90032 | M7: West | N7: FUR-FU-10001487 | O7: Furniture | P7: Furnishings | Q7: Eldon Expressions Wood and Plastic Desk Accessories, Cherry Wood | R7: 48.86 | S7: 7 | T7: 0 | U7: 14.1694
A8: 7 | B8: CA-2014-115812 | C8: 41799 | D8: 41804 | E8: Standard Class | F8: BH-11710 | G8: Brosina Hoffman | H8: Consumer | I8: United States | J8: Los Angeles | K8: California | L8: 90032 | M8: West | N8: OFF-AR-10002833 | O8: Office Supplies | P8: Art | Q8: Newell 322 | R8: 7.28 | S8: 4 | T8: 0 | U8: 1.9656
A9: 8 | B9: CA-2014-115812 | C9: 41799 | D9: 41804 | E9: Standard Class | F9: BH-11710 | G9: Brosina Hoffman | H9: Consumer | I9: United States | J9: Los Angeles | K9: California | L9: 90032 | M9: West | N9: TEC-PH-10002275 | O9: Technology | P9: Phones | Q9: Mitel 5320 IP Phone VoIP phone | R9: 907.152 | S9: 6 | T9: 0.2 | U9: 90.7152
A10: 9 | B10: CA-2014-115812 | C10: 41799 | D10: 41804 | E10: Standard Class | F10: BH-11710 | G10: Brosina Hoffman | H10: Consumer | I10: United States | J10: Los Angeles | K10: California | L10: 90032 | M10: West | N10: OFF-BI-10003910 | O10: Office Supplies | P10: Binders | Q10: DXL Angle-View Binders with Locking Rings by Samsill | R10: 18.504 | S10: 3 | T10: 0.2 | U10: 5.7825
A11: 10 | B11: CA-2014-115812 | C11: 41799 | D11: 41804 | E11: Standard Class | F11: BH-11710 | G11: Brosina Hoffman | H11: Consumer | I11: United States | J11: Los Angeles | K11: California | L11: 90032 | M11: West | N11: OFF-AP-10002892 | O11: Office Supplies | P11: Appliances | Q11: Belkin F5C206VTEL 6 Outlet Surge | R11: 114.9 | S11: 5 | T11: 0 | U11: 34.47
A12: 11 | B12: CA-2014-115812 | C12: 41799 | D12: 41804 | E12: Standard Class | F12: BH-11710 | G12: Brosina Hoffman | H12: Consumer | I12: United States | J12: Los Angeles | K12: California | L12: 90032 | M12: West | N12: FUR-TA-10001539 | O12: Furniture | P12: Tables | Q12: Chromcraft Rectangular Conference Tables | R12: 1706.184 | S12: 9 | T12: 0.2 | U12: 85.3092
A13: 12 | B13: CA-2014-115812 | C13: 41799 | D13: 41804 | E13: Standard Class | F13: BH-11710 | G13: Brosina Hoffman | H13: Consumer | I13: United States | J13: Los Angeles | K13: California | L13: 90032 | M13: West | N13: TEC-PH-10002033 | O13: Technology | P13: Phones | Q13: Konftel 250 Conference phone - Charcoal black | R13: 911.424 | S13: 4 | T13: 0.2 | U13: 68.3568
... A9995: 9994 | B9995: CA-2017-119914 | C9995: 42859 | D9995: 42864 | E9995: Second Class | F9995: CC-12220 | G9995: Chris Cortes | H9995: Consumer | I9995: United States | J9995: Westminster | K9995: California | L9995: 92683 | M9995: West | N9995: OFF-AP-10002684 | O9995: Office Supplies | P9995: Appliances | Q9995: Acco 7-Outlet Masterpiece Power Center, Wihtout Fax/Phone Line Protection | R9995: 243.16 | S9995: 2 | T9995: 0 | U9995: 72.948

Sheet Working
A1: KPI | B1: value | D1: Category | E1: Total Sales | F1: Order Count | G1: Average Profit
A2: Total Sales | B2: =SUM('Raw Data'!R:R) -> 2297200.9 | D2: Furniture | E2: =SUMIFS('Raw Data'!R:R,'Raw Data'!O:O,D2) -> 741999.8 | F2: =COUNTIFS('Raw Data'!O:O,D2) -> 2121 | G2: =AVERAGEIFS('Raw Data'!U:U,'Raw Data'!O:O,D2) -> 8.6993271
A3: Total Profit | B3: =SUM('Raw Data'!U:U) -> 286397.02 | D3: Office Supplies | E3: =SUMIFS('Raw Data'!R:R,'Raw Data'!O:O,D3) -> 719047.03 | F3: =COUNTIFS('Raw Data'!O:O,D3) -> 6026 | G3: =AVERAGEIFS('Raw Data'!U:U,'Raw Data'!O:O,D3) -> 20.32705
A4: Total Quantity | B4: =SUM('Raw Data'!S:S) -> 37873 | D4: Technology | E4: =SUMIFS('Raw Data'!R:R,'Raw Data'!O:O,D4) -> 836154.03 | F4: =COUNTIFS('Raw Data'!O:O,D4) -> 1847 | G4: =AVERAGEIFS('Raw Data'!U:U,'Raw Data'!O:O,D4) -> 78.752002
A5: Average Sales | B5: =AVERAGE('Raw Data'!R:R) -> 229.858
A6: Average Profit | B6: =AVERAGE('Raw Data'!U:U) -> 28.656896
A7: Number of Order | B7: =COUNTA('Raw Data'!B:B)-1 -> 9994 | D7: Region
A8: Average Discount | B8: =AVERAGE('Raw Data'!T:T) -> 0.15620272 | D8: Central | E8: =SUMIFS('Raw Data'!R:R,'Raw Data'!M:M,D8) -> 501239.89
D9: East | E9: =SUMIFS('Raw Data'!R:R,'Raw Data'!M:M,D9) -> 678781.24
D10: South | E10: =SUMIFS('Raw Data'!R:R,'Raw Data'!M:M,D10) -> 391721.91
D11: West | E11: =SUMIFS('Raw Data'!R:R,'Raw Data'!M:M,D11) -> 725457.82
D14: Segment
D15: Consumer | E15: =SUMIFS('Raw Data'!R:R,'Raw Data'!H:H,D15) -> 1161401.3
D16: Corporate | E16: =SUMIFS('Raw Data'!R:R,'Raw Data'!H:H,D16) -> 706146.37
D17: Home Office | E17: =SUMIFS('Raw Data'!R:R,'Raw Data'!H:H,D17) -> 429653.15
